2021-02-05 04:54:12,459 -  nornir.core -     INFO -        run() - Running task 'data_validation' with args {} on 2 hosts
2021-02-05 04:54:12,463 -  nornir.core -     INFO -        run() - Running task 'nc_deployment' with args {} on 2 hosts
2021-02-05 04:54:15,138 -  nornir.core -     INFO -        run() - Running task 'cli_stats' with args {} on 2 hosts
2021-02-05 04:54:54,329 -  nornir.core -     INFO -        run() - Running task 'data_validation' with args {} on 2 hosts
2021-02-05 04:54:54,333 -  nornir.core -     INFO -        run() - Running task 'nc_deployment' with args {} on 2 hosts
2021-02-05 04:54:56,702 -  nornir.core -     INFO -        run() - Running task 'cli_stats' with args {} on 2 hosts
2021-02-05 05:17:15,092 -  nornir.core -     INFO -        run() - Running task 'data_validation' with args {} on 2 hosts
2021-02-05 05:17:15,096 -  nornir.core -     INFO -        run() - Running task 'nc_deployment' with args {} on 2 hosts
2021-02-05 05:17:25,636 - nornir.core.task -    ERROR -      start() - Host 'R3_SROS_PE': task 'netconf_edit_config' failed with traceback:
Traceback (most recent call last):
  File "/home/vscode/.local/lib/python3.8/site-packages/scrapli/transport/ptyprocess.py", line 395, in read
    s = self.fileobj.read1(size)
OSError: [Errno 5] Input/output error

During handling of the above exception, another exception occurred:

Traceback (most recent call last):
  File "/home/vscode/.local/lib/python3.8/site-packages/scrapli_netconf/transport/systemssh.py", line 103, in _authenticate
    new_output = self.session.read()
  File "/home/vscode/.local/lib/python3.8/site-packages/scrapli/transport/ptyprocess.py", line 400, in read
    raise EOFError("End Of File (EOF). Exception style platform.")
EOFError: End Of File (EOF). Exception style platform.

During handling of the above exception, another exception occurred:

Traceback (most recent call last):
  File "/home/vscode/.local/lib/python3.8/site-packages/nornir/core/task.py", line 98, in start
    r = self.task(self, **self.params)
  File "/home/vscode/.local/lib/python3.8/site-packages/nornir_scrapli/tasks/netconf_edit_config.py", line 38, in netconf_edit_config
    scrapli_conn = task.host.get_connection("scrapli_netconf", task.nornir.config)
  File "/home/vscode/.local/lib/python3.8/site-packages/nornir/core/inventory.py", line 440, in get_connection
    self.open_connection(
  File "/home/vscode/.local/lib/python3.8/site-packages/nornir/core/inventory.py", line 492, in open_connection
    conn_obj.open(
  File "/home/vscode/.local/lib/python3.8/site-packages/nornir_scrapli/connection.py", line 166, in open
    connection.open()
  File "/home/vscode/.local/lib/python3.8/site-packages/scrapli_netconf/driver/driver.py", line 64, in open
    login_bytes = self.transport.open_netconf()
  File "/home/vscode/.local/lib/python3.8/site-packages/scrapli_netconf/transport/systemssh.py", line 38, in open_netconf
    login_bytes = self._open_netconf_pty()
  File "/home/vscode/.local/lib/python3.8/site-packages/scrapli_netconf/transport/systemssh.py", line 58, in _open_netconf_pty
    login_bytes: bytes = self._authenticate()
  File "/home/vscode/.local/lib/python3.8/site-packages/scrapli/decorators.py", line 113, in decorate
    return self.multiprocessing_timeout(
  File "/home/vscode/.local/lib/python3.8/site-packages/scrapli/decorators.py", line 286, in multiprocessing_timeout
    result = future.get(timeout=self.timeout_duration)
  File "/usr/lib/python3.8/multiprocessing/pool.py", line 771, in get
    raise self._value
  File "/usr/lib/python3.8/multiprocessing/pool.py", line 125, in worker
    result = (True, func(*args, **kwds))
  File "/home/vscode/.local/lib/python3.8/site-packages/scrapli_netconf/transport/systemssh.py", line 107, in _authenticate
    self._ssh_message_handler(output=output)
  File "/home/vscode/.local/lib/python3.8/site-packages/scrapli/transport/systemssh.py", line 286, in _ssh_message_handler
    raise ScrapliAuthenticationFailed(msg)
scrapli.exceptions.ScrapliAuthenticationFailed: Timed out connecting to host 192.168.0.222

2021-02-05 05:17:25,638 - nornir.core.task -    ERROR -      start() - Host 'R3_SROS_PE': task 'nc_deployment' failed with traceback:
Traceback (most recent call last):
  File "/home/vscode/.local/lib/python3.8/site-packages/nornir/core/task.py", line 98, in start
    r = self.task(self, **self.params)
  File "norconf.py", line 66, in nc_deployment
    deploy_config = task.run(
  File "/home/vscode/.local/lib/python3.8/site-packages/nornir/core/task.py", line 168, in run
    raise NornirSubTaskError(task=run_task, result=r)
nornir.core.exceptions.NornirSubTaskError: Subtask: netconf_edit_config (failed)


2021-02-05 05:17:25,639 -  nornir.core -     INFO -        run() - Running task 'cli_stats' with args {} on 2 hosts
2021-02-05 05:18:55,375 -  nornir.core -     INFO -        run() - Running task 'data_validation' with args {} on 2 hosts
2021-02-05 05:18:55,379 -  nornir.core -     INFO -        run() - Running task 'nc_deployment' with args {} on 2 hosts
2021-02-05 05:18:58,801 -  nornir.core -     INFO -        run() - Running task 'cli_stats' with args {} on 2 hosts
2021-02-05 05:19:55,777 -  nornir.core -     INFO -        run() - Running task 'data_validation' with args {} on 2 hosts
2021-02-05 05:19:55,781 -  nornir.core -     INFO -        run() - Running task 'nc_deployment' with args {} on 2 hosts
2021-02-05 05:19:58,986 -  nornir.core -     INFO -        run() - Running task 'cli_stats' with args {} on 2 hosts
2021-02-05 05:27:23,943 -  nornir.core -     INFO -        run() - Running task 'data_validation' with args {} on 2 hosts
2021-02-05 05:27:23,946 -  nornir.core -     INFO -        run() - Running task 'nc_deployment' with args {} on 2 hosts
2021-02-05 05:27:26,730 -  nornir.core -     INFO -        run() - Running task 'cli_stats' with args {} on 2 hosts
2021-02-05 05:52:16,492 -  nornir.core -     INFO -        run() - Running task 'data_validation' with args {} on 2 hosts
2021-02-05 05:52:16,496 -  nornir.core -     INFO -        run() - Running task 'nc_deployment' with args {} on 2 hosts
2021-02-05 05:52:19,125 -  nornir.core -     INFO -        run() - Running task 'cli_stats' with args {} on 2 hosts
2021-02-05 05:52:27,435 -  nornir.core -     INFO -        run() - Running task 'routing_validation' with args {} on 2 hosts
2021-02-05 05:54:01,138 -  nornir.core -     INFO -        run() - Running task 'data_validation' with args {} on 2 hosts
2021-02-05 05:54:01,141 -  nornir.core -     INFO -        run() - Running task 'nc_deployment' with args {} on 2 hosts
2021-02-05 05:54:11,646 - nornir.core.task -    ERROR -      start() - Host 'R3_SROS_PE': task 'netconf_edit_config' failed with traceback:
Traceback (most recent call last):
  File "/home/vscode/.local/lib/python3.8/site-packages/scrapli/transport/ptyprocess.py", line 395, in read
    s = self.fileobj.read1(size)
OSError: [Errno 5] Input/output error

During handling of the above exception, another exception occurred:

Traceback (most recent call last):
  File "/home/vscode/.local/lib/python3.8/site-packages/scrapli_netconf/transport/systemssh.py", line 103, in _authenticate
    new_output = self.session.read()
  File "/home/vscode/.local/lib/python3.8/site-packages/scrapli/transport/ptyprocess.py", line 400, in read
    raise EOFError("End Of File (EOF). Exception style platform.")
EOFError: End Of File (EOF). Exception style platform.

During handling of the above exception, another exception occurred:

Traceback (most recent call last):
  File "/home/vscode/.local/lib/python3.8/site-packages/nornir/core/task.py", line 98, in start
    r = self.task(self, **self.params)
  File "/home/vscode/.local/lib/python3.8/site-packages/nornir_scrapli/tasks/netconf_edit_config.py", line 38, in netconf_edit_config
    scrapli_conn = task.host.get_connection("scrapli_netconf", task.nornir.config)
  File "/home/vscode/.local/lib/python3.8/site-packages/nornir/core/inventory.py", line 440, in get_connection
    self.open_connection(
  File "/home/vscode/.local/lib/python3.8/site-packages/nornir/core/inventory.py", line 492, in open_connection
    conn_obj.open(
  File "/home/vscode/.local/lib/python3.8/site-packages/nornir_scrapli/connection.py", line 166, in open
    connection.open()
  File "/home/vscode/.local/lib/python3.8/site-packages/scrapli_netconf/driver/driver.py", line 64, in open
    login_bytes = self.transport.open_netconf()
  File "/home/vscode/.local/lib/python3.8/site-packages/scrapli_netconf/transport/systemssh.py", line 38, in open_netconf
    login_bytes = self._open_netconf_pty()
  File "/home/vscode/.local/lib/python3.8/site-packages/scrapli_netconf/transport/systemssh.py", line 58, in _open_netconf_pty
    login_bytes: bytes = self._authenticate()
  File "/home/vscode/.local/lib/python3.8/site-packages/scrapli/decorators.py", line 113, in decorate
    return self.multiprocessing_timeout(
  File "/home/vscode/.local/lib/python3.8/site-packages/scrapli/decorators.py", line 286, in multiprocessing_timeout
    result = future.get(timeout=self.timeout_duration)
  File "/usr/lib/python3.8/multiprocessing/pool.py", line 771, in get
    raise self._value
  File "/usr/lib/python3.8/multiprocessing/pool.py", line 125, in worker
    result = (True, func(*args, **kwds))
  File "/home/vscode/.local/lib/python3.8/site-packages/scrapli_netconf/transport/systemssh.py", line 107, in _authenticate
    self._ssh_message_handler(output=output)
  File "/home/vscode/.local/lib/python3.8/site-packages/scrapli/transport/systemssh.py", line 286, in _ssh_message_handler
    raise ScrapliAuthenticationFailed(msg)
scrapli.exceptions.ScrapliAuthenticationFailed: Timed out connecting to host 192.168.0.222

2021-02-05 05:54:11,647 - nornir.core.task -    ERROR -      start() - Host 'R3_SROS_PE': task 'nc_deployment' failed with traceback:
Traceback (most recent call last):
  File "/home/vscode/.local/lib/python3.8/site-packages/nornir/core/task.py", line 98, in start
    r = self.task(self, **self.params)
  File "norconf.py", line 66, in nc_deployment
    deploy_config = task.run(
  File "/home/vscode/.local/lib/python3.8/site-packages/nornir/core/task.py", line 168, in run
    raise NornirSubTaskError(task=run_task, result=r)
nornir.core.exceptions.NornirSubTaskError: Subtask: netconf_edit_config (failed)


2021-02-05 05:54:11,648 -  nornir.core -     INFO -        run() - Running task 'cli_stats' with args {} on 2 hosts
2021-02-05 05:54:20,401 -  nornir.core -     INFO -        run() - Running task 'routing_validation' with args {} on 2 hosts
2021-02-05 05:54:55,396 -  nornir.core -     INFO -        run() - Running task 'data_validation' with args {} on 2 hosts
2021-02-05 05:54:55,400 -  nornir.core -     INFO -        run() - Running task 'nc_deployment' with args {} on 2 hosts
2021-02-05 05:54:57,877 -  nornir.core -     INFO -        run() - Running task 'cli_stats' with args {} on 2 hosts
2021-02-05 05:55:06,410 -  nornir.core -     INFO -        run() - Running task 'routing_validation' with args {} on 2 hosts
2021-02-05 05:55:11,529 - nornir.core.task -    ERROR -      start() - Host 'R3_SROS_PE': task 'routing_validation' failed with traceback:
Traceback (most recent call last):
  File "/home/vscode/.local/lib/python3.8/site-packages/nornir/core/task.py", line 98, in start
    r = self.task(self, **self.params)
  File "norconf.py", line 122, in routing_validation
    assert '0.00% packet loss' in ping_iosxrlo.result
AssertionError

2021-02-05 05:55:48,394 -  nornir.core -     INFO -        run() - Running task 'data_validation' with args {} on 2 hosts
2021-02-05 05:55:48,397 -  nornir.core -     INFO -        run() - Running task 'nc_deployment' with args {} on 2 hosts
2021-02-05 05:55:51,713 -  nornir.core -     INFO -        run() - Running task 'cli_stats' with args {} on 2 hosts
2021-02-05 05:56:02,380 -  nornir.core -     INFO -        run() - Running task 'routing_validation' with args {} on 2 hosts
